### What & Why

所谓Promise，简单说就是一个容器，里面保存着某个未来才会结束的事件（通常是一个异步操作）的结果。

方便处理异步问题，解决callback hell

### Pros & Cons

Promise对象代表一个异步操作，有三种状态：
1. pending（进行中）
2. fulfilled（已成功）
3. rejected（已失败）

Promise对象的状态改变，只有两种可能：从pending变为fulfilled和从pending变为rejected。

Promise对象有以下两个特点：
1. 对象的状态不受外界影响。Promise 内部的错误不会影响到 Promise 外部的代码，通俗的说法就是“Promise 会吃掉错误”。
1. 一旦状态改变，就不会再变。

Promise缺点：
1. 无法取消Promise，一旦新建它就会立即执行，无法中途取消。
2. 如果不设置回调函数，Promise内部抛出的错误，不会反应到外部。
3. 当处于pending状态时，无法得知目前进展到哪一个阶段（刚刚开始还是即将完成）。
4. 语义不明，代码冗余。

```
let p = new Promise((resolve, reject) => { 
	resolve("ok"); // 会异步执行
	console.log("yes"); //会同步执行，调用resolve或reject并不会导致这里不执行
	reject("no");  // 不会执行，因为特点2
})

p.then((resp) => console.log(resp))
 .catch((err) => console.log(err))

// yes
// ok
```


### 基本用法

```
promise.then((value) => {
  // success
}, (error) => {
  // failure
});

// 等价
// 建议写法

promise
	.then((value) => {
	  	// success
	})
	.catch((err) => {
		// fail	
	});

// 等价

promise
	.then((value) => {
	  	// success
	})
	.then(null, (err) => {
		// fail	
	});
```

```
const p1 = new Promise(function (resolve, reject) { // ... });
const p2 = new Promise(function (resolve, reject) { 
	// ... 
	resolve(p1); 
})

p2.then(...) //注意，此时的p2的状态已经无法获得，这样获得的是p1的状态
```

### Promise.prototype.then()

then方法默认返回一个新的Promise实例（注意，不是原来那个Promise实例）

```
var x = new Promise((resolve, reject) => { 
	resolve("ok") // 会执行
})

var y = x.then((resp) => console.log(resp))

// ok
// x -> Promise {<resolved>: "ok"}
// y -> Promise {<resolved>: undefined}
```

```
var x = new Promise((resolve, reject) => { 
	resolve("ok")
})

var y = x.then((resp) => {
	return Promise.resolve("here") // 覆盖默认返回的Promise
})
.then((resp => console.log(resp)))

// here
// x -> Promise {<resolved>: "ok"}
// y -> Promise {<resolved>: undefined}

```

### Promise.prototype.catch()

Promise.prototype.catch方法是.then(null, rejection)的别名

```
const promise = new Promise(function(resolve, reject) {
  try {
    throw new Error('test');
  } catch(e) {
    reject(e);
  }
});
promise.catch(function(error) {
  console.log(error);
});

// 等价

const promise = new Promise(function(resolve, reject) {
  reject(new Error('test'));
});
promise.catch(function(error) {
  console.log(error);
});
```

Promise 对象的错误具有“冒泡”性质，会一直向后传递，直到被捕获为止。

### Promise.prototype.finally()

用于指定不管 Promise 对象最后状态如何，都会执行的操作。finally方法里面的操作，应该是与状态无关的，不依赖于 Promise 的执行结果。

finally方法总是会返回原来的值。

```
// resolve 的值是 undefined
Promise.resolve(2).then(() => {}, () => {})

// resolve 的值是 2，因为它的本质是then语句，默认返回了对应的值
Promise.resolve(2).finally(() => {})

// reject 的值是 undefined
Promise.reject(3).then(() => {}, () => {})

// reject 的值是 3
Promise.reject(3).finally(() => {})
```

### Promise.all()

```
const p = Promise.all([p1, p2, p3]);
```

- Promise.all方法接受一个数组作为参数，p1、p2、p3都是 Promise 实例，如果不是，就会先调用下面讲到的Promise.resolve方法，将参数转为 Promise 实例，再进一步处理。
- 只有p1、p2、p3的状态都变成fulfilled，p的状态才会变成fulfilled，此时p1、p2、p3的返回值组成一个数组，传递给p的回调函数。
- 只要p1、p2、p3之中有一个被rejected，p的状态就变成rejected，此时第一个被reject的实例的返回值，会传递给p的回调函数。

如果作为参数的 Promise 实例，自己定义了catch方法，那么它一旦被rejected，并不会触发Promise.all()的catch方法。

```
var p1 = new Promise((resolve, reject) => {
  resolve('hello');
})
.then(result => result)
.catch(e => console.log("catch from p1 catch"));

var p2 = new Promise((resolve, reject) => {
  throw new Error('报错了');
})
.then(result => result)
.catch(e => console.log("catch from p2 catch"));

Promise.all([p1, p2])
.then(result => console.log(result))
.catch(e => console.log("catch from all"));

// catch from p2 catch
// ["hello", undefined]
```

因为catch函数返回的是resolve的Promise，所以all认为p2是resolve的，就不执行all的catch

如果p2没有自己的catch方法，就会调用Promise.all()的catch方法。

### Promise.race()

第一个resolve，只返回第一个的数据；第一个reject，就catch，终止其他的请求。

### Promise.resolve()

转化为Promise对象，分四种条件。略

```
setTimeout(function () {
  console.log('three');
}, 0);

Promise.resolve().then(function () {
  console.log('two');
});

console.log('one');

// one
// two
// three
```

需要注意的是，立即resolve的 Promise 对象，是在本轮“事件循环”（event loop）的结束时，而不是在下一轮“事件循环”的开始时。

### Promise.reject()

### Promise.try()

未完待续


